<mujoco model="aliengo">
  <compiler angle="radian"/>

  <worldbody>
    <geom size="0.3235 0.075 0.056" type="box" rgba="1 0.423529 0.0392157 1"/>
    <geom size="0.0005 0.0005 0.0005" type="box" rgba="0.8 0 0 1"/>
    <geom size="0.035 0.01" pos="0.139985 -0.051 0" quat="0.707107 0 0.707107 0" type="cylinder" rgba="0 0.8 0 1"/>
    <geom size="0.035 0.01" pos="0.139985 0.051 0" quat="0.707107 0 0.707107 0" type="cylinder" rgba="0 0.8 0 1"/>
    <geom size="0.035 0.01" pos="-0.139985 -0.051 0" quat="0.707107 0 0.707107 0" type="cylinder" rgba="0 0.8 0 1"/>
    <geom size="0.035 0.01" pos="-0.139985 0.051 0" quat="0.707107 0 0.707107 0" type="cylinder" rgba="0 0.8 0 1"/>
    <body name="FR_hip" pos="0.2407 -0.051 0">
      <inertial pos="-0.0206763 -0.0161444 -1.39762e-05" quat="0.58092 0.574831 0.412459 0.402465" mass="2.139" diaginertia="0.0043606 0.0043277 0.00233028"/>
      <joint name="FR_hip_joint" pos="0 0 0" axis="1 0 0" range="-1.22173 1.22173" actuatorfrcrange="-35.278 35.278"/>
      <geom size="0.046 0.0209" pos="0 -0.083 0" quat="0.707107 0.707107 0 0" type="cylinder" rgba="1 0.423529 0.0392157 1"/>
      <geom size="0.035 0.01" pos="0 -0.0298 0" quat="0.707107 0.707107 0 0" type="cylinder" rgba="0 0.8 0 1"/>
      <body name="FR_thigh" pos="0 -0.0868 0">
        <inertial pos="-0.00464705 0.0202825 -0.039947" quat="0.994998 -0.0906147 0.0414285 -0.0071304" mass="0.771" diaginertia="0.00560787 0.004847 0.00135111"/>
        <joint name="FR_thigh_joint" pos="0 0 0" axis="0 1 0" actuatorfrcrange="-35.278 35.278"/>
        <geom size="0.125 0.0187 0.0215" pos="0 0 -0.125" quat="0.707107 0 0.707107 0" type="box" rgba="1 0.423529 0.0392157 1"/>
        <geom size="0.035 0.01" pos="0 0.0997 0" quat="0.707107 0.707107 0 0" type="cylinder" rgba="0 0.8 0 1"/>
        <body name="FR_calf" pos="0 0 -0.25">
          <inertial pos="0.00215606 4.88427e-05 -0.166671" quat="0.708049 0.000982931 0.00120829 0.706161" mass="0.267" diaginertia="0.00269606 0.00268354 5.47714e-05"/>
          <joint name="FR_calf_joint" pos="0 0 0" axis="0 1 0" range="-2.77507 -0.645772" actuatorfrcrange="-44.4 44.4"/>
          <geom size="0.125 0.0104 0.008" pos="0 0 -0.125" quat="0.707107 0 0.707107 0" type="box" rgba="1 0.423529 0.0392157 1"/>
          <geom size="0.0265" pos="0 0 -0.25" rgba="0 0.8 0 1"/>
        </body>
      </body>
    </body>
    <body name="FL_hip" pos="0.2407 0.051 0">
      <inertial pos="-0.0206763 0.0161444 -1.39762e-05" quat="0.402465 0.412459 0.574831 0.58092" mass="2.139" diaginertia="0.0043606 0.0043277 0.00233028"/>
      <joint name="FL_hip_joint" pos="0 0 0" axis="1 0 0" range="-1.22173 1.22173" actuatorfrcrange="-35.278 35.278"/>
      <geom size="0.046 0.0209" pos="0 0.083 0" quat="0.707107 0.707107 0 0" type="cylinder" rgba="1 0.423529 0.0392157 1"/>
      <geom size="0.035 0.01" pos="0 0.0298 0" quat="0.707107 0.707107 0 0" type="cylinder" rgba="0 0.8 0 1"/>
      <body name="FL_thigh" pos="0 0.0868 0">
        <inertial pos="-0.00464705 -0.0202825 -0.039947" quat="0.994998 0.0906147 0.0414285 0.0071304" mass="0.771" diaginertia="0.00560787 0.004847 0.00135111"/>
        <joint name="FL_thigh_joint" pos="0 0 0" axis="0 1 0" actuatorfrcrange="-35.278 35.278"/>
        <geom size="0.125 0.0187 0.0215" pos="0 0 -0.125" quat="0.707107 0 0.707107 0" type="box" rgba="1 0.423529 0.0392157 1"/>
        <geom size="0.035 0.01" pos="0 -0.0997 0" quat="0.707107 0.707107 0 0" type="cylinder" rgba="0 0.8 0 1"/>
        <body name="FL_calf" pos="0 0 -0.25">
          <inertial pos="0.00215606 4.88427e-05 -0.166671" quat="0.708049 0.000982931 0.00120829 0.706161" mass="0.267" diaginertia="0.00269606 0.00268354 5.47714e-05"/>
          <joint name="FL_calf_joint" pos="0 0 0" axis="0 1 0" range="-2.77507 -0.645772" actuatorfrcrange="-44.4 44.4"/>
          <geom size="0.125 0.0104 0.008" pos="0 0 -0.125" quat="0.707107 0 0.707107 0" type="box" rgba="1 0.423529 0.0392157 1"/>
          <geom size="0.0265" pos="0 0 -0.25" rgba="0 0.8 0 1"/>
        </body>
      </body>
    </body>
    <body name="RR_hip" pos="-0.2407 -0.051 0">
      <inertial pos="0.0206763 -0.0161444 -1.39762e-05" quat="0.412459 0.402465 0.58092 0.574831" mass="2.139" diaginertia="0.0043606 0.0043277 0.00233028"/>
      <joint name="RR_hip_joint" pos="0 0 0" axis="1 0 0" range="-1.22173 1.22173" actuatorfrcrange="-35.278 35.278"/>
      <geom size="0.046 0.0209" pos="0 -0.083 0" quat="0.707107 0.707107 0 0" type="cylinder" rgba="1 0.423529 0.0392157 1"/>
      <geom size="0.035 0.01" pos="0 -0.0298 0" quat="0.707107 0.707107 0 0" type="cylinder" rgba="0 0.8 0 1"/>
      <body name="RR_thigh" pos="0 -0.0868 0">
        <inertial pos="-0.00464705 0.0202825 -0.039947" quat="0.994998 -0.0906147 0.0414285 -0.0071304" mass="0.771" diaginertia="0.00560787 0.004847 0.00135111"/>
        <joint name="RR_thigh_joint" pos="0 0 0" axis="0 1 0" actuatorfrcrange="-35.278 35.278"/>
        <geom size="0.125 0.0187 0.0215" pos="0 0 -0.125" quat="0.707107 0 0.707107 0" type="box" rgba="1 0.423529 0.0392157 1"/>
        <geom size="0.035 0.01" pos="0 0.0997 0" quat="0.707107 0.707107 0 0" type="cylinder" rgba="0 0.8 0 1"/>
        <body name="RR_calf" pos="0 0 -0.25">
          <inertial pos="0.00215606 4.88427e-05 -0.166671" quat="0.708049 0.000982931 0.00120829 0.706161" mass="0.267" diaginertia="0.00269606 0.00268354 5.47714e-05"/>
          <joint name="RR_calf_joint" pos="0 0 0" axis="0 1 0" range="-2.77507 -0.645772" actuatorfrcrange="-44.4 44.4"/>
          <geom size="0.125 0.0104 0.008" pos="0 0 -0.125" quat="0.707107 0 0.707107 0" type="box" rgba="1 0.423529 0.0392157 1"/>
          <geom size="0.0265" pos="0 0 -0.25" rgba="0 0.8 0 1"/>
        </body>
      </body>
    </body>
    <body name="RL_hip" pos="-0.2407 0.051 0">
      <inertial pos="0.0206763 0.0161444 -1.39762e-05" quat="0.574831 0.58092 0.402465 0.412459" mass="2.139" diaginertia="0.0043606 0.0043277 0.00233028"/>
      <joint name="RL_hip_joint" pos="0 0 0" axis="1 0 0" range="-1.22173 1.22173" actuatorfrcrange="-35.278 35.278"/>
      <geom size="0.046 0.0209" pos="0 0.083 0" quat="0.707107 0.707107 0 0" type="cylinder" rgba="1 0.423529 0.0392157 1"/>
      <geom size="0.035 0.01" pos="0 0.0298 0" quat="0.707107 0.707107 0 0" type="cylinder" rgba="0 0.8 0 1"/>
      <body name="RL_thigh" pos="0 0.0868 0">
        <inertial pos="-0.00464705 -0.0202825 -0.039947" quat="0.994998 0.0906147 0.0414285 0.0071304" mass="0.771" diaginertia="0.00560787 0.004847 0.00135111"/>
        <joint name="RL_thigh_joint" pos="0 0 0" axis="0 1 0" actuatorfrcrange="-35.278 35.278"/>
        <geom size="0.125 0.0187 0.0215" pos="0 0 -0.125" quat="0.707107 0 0.707107 0" type="box" rgba="1 0.423529 0.0392157 1"/>
        <geom size="0.035 0.01" pos="0 -0.0997 0" quat="0.707107 0.707107 0 0" type="cylinder" rgba="0 0.8 0 1"/>
        <body name="RL_calf" pos="0 0 -0.25">
          <inertial pos="0.00215606 4.88427e-05 -0.166671" quat="0.708049 0.000982931 0.00120829 0.706161" mass="0.267" diaginertia="0.00269606 0.00268354 5.47714e-05"/>
          <joint name="RL_calf_joint" pos="0 0 0" axis="0 1 0" range="-2.77507 -0.645772" actuatorfrcrange="-44.4 44.4"/>
          <geom size="0.125 0.0104 0.008" pos="0 0 -0.125" quat="0.707107 0 0.707107 0" type="box" rgba="1 0.423529 0.0392157 1"/>
          <geom size="0.0265" pos="0 0 -0.25" rgba="0 0.8 0 1"/>
        </body>
      </body>
    </body>
  </worldbody>
</mujoco>
